# 不要让异常成为不可控因素

有时候在协程中产生了一个panic，如果不对其进行处理，整个进程都会挂掉。特别是使用第三方库的时候一定要小心，冷不丁一个异常出来，这就是不可控因素。所以在协程开始的地方使用recover就很有必要了。虽然这个协程挂了，其他的协程还能继续跑。调试时可以用debug.PrintStack()打印协程挂掉的调用栈。

```
package main

import (
	"context"
	"fmt"
	"os"
	"os/signal"
	//"runtime/debug"
	"sync"
	"syscall"
	"time"
)

func task(ctx context.Context)  {
	for {
		select {
		case <-ctx.Done():
			return
		default:
		}
		time.Sleep(time.Second)
		panic("unexpected error")
	}
}

func main()  {
	ctx, cancel := context.WithCancel(context.Background())

	w := sync.WaitGroup{}
	w.Add(1)
	go func() {
		defer w.Done()
		defer func() {
			if err := recover(); err != nil {
				fmt.Printf("task exit with error: %v\n", err)
				//debug.PrintStack()
			}
		}()
		task(ctx)
		fmt.Println("task exit")
	}()

	signalChan := make(chan os.Signal, 1)
	signal.Notify(signalChan, syscall.SIGINT, syscall.SIGTERM)
	<-signalChan
	cancel()
	w.Wait()
	fmt.Println("main exit")
}

```

运行结果：
```
task exit with error: unexpected error
main exit
```
